2013-12-22 00:50:22.458359- /getLabels called
Exception on /login2 [GET]
Traceback (most recent call last):
  File "/Library/Python/2.7/site-packages/flask/app.py", line 1687, in wsgi_app
    response = self.full_dispatch_request()
  File "/Library/Python/2.7/site-packages/flask/app.py", line 1360, in full_dispatch_request
    rv = self.handle_user_exception(e)
  File "/Library/Python/2.7/site-packages/flask/app.py", line 1358, in full_dispatch_request
    rv = self.dispatch_request()
  File "/Library/Python/2.7/site-packages/flask/app.py", line 1344, in dispatch_request
    return self.view_functions[rule.endpoint](**req.view_args)
  File "/Users/asraj/github/vmedia-heroku/app.py", line 32, in index2
    return send_file(open('views/index.html').read())
  File "/Library/Python/2.7/site-packages/flask/helpers.py", line 568, in send_file
    file = open(filename, 'rb')
IOError: [Errno 63] File name too long: '/Users/asraj/github/vmedia-heroku/<!DOCTYPE html>\r\n<html lang="en" ng-app="varsityframework">\r\n<head>\r\n\t<meta charset="utf-8">\r\n\t<title>Welcome - Varsity Media</title>\r\n\t<meta name="viewport" content="width=device-width, initial-scale=1.0">\r\n\t<meta name="description" content="">\r\n\t<meta name="author" content="">\r\n\t<link href="css/bootstrap.css" rel="stylesheet" />\r\n\t<link href="css/style.css" rel="stylesheet" />\r\n\t<link href="css/custom.css" rel="stylesheet" /> \r\n\t<script src="js/lib/jquery-1.8.2.min.js"></script>\r\n\t<script type="text/javascript" language="javascript" src="js/lib/jquery.carouFredSel-6.2.1.js"></script>\r\n\t<script src="js/lib/bootstrap.min.js"></script> \r\n\t<script src="js/lib/angular.js"></script> \t\r\n\t<script src="js/core/App.js"></script>\r\n\t<script src="js/core/videoController.js"></script>\r\n\t<script src="js/core/directives.js"></script>\r\n\t<script src="js/core/loginController.js"></script>\r\n\t\r\n\t <!-- HTML5 shim and Respond.js IE8 support of HTML5 elements and media queries -->\r\n    <!--[if lt IE 9]>\r\n      <script src="https://oss.maxcdn.com/libs/html5shiv/3.7.0/html5shiv.js"></script>\r\n      <script src="https://oss.maxcdn.com/libs/respond.js/1.3.0/respond.min.js"></script>\r\n    <![endif]-->\r\n\t\r\n\t\r\n</head>\r\n<body>\r\n\t<div class=\'container\'>\r\n\t\t<div class="navbar navbar-default navbar-inverse" role="navigation">\r\n\t\t\t<div class="navbar-header">\r\n\t\t\t  <button type="button" class="navbar-toggle" data-toggle="collapse" data-target=".navbar-collapse">\r\n\t\t\t\t<span class="sr-only">Toggle navigation</span>\r\n\t\t\t\t<span class="icon-bar"></span>\r\n\t\t\t\t<span class="icon-bar"></span>\r\n\t\t\t\t<span class="icon-bar"></span>\r\n\t\t\t  </button>\r\n\t\t\t  <a class="navbar-brand" href="#/home">Varsity Media</a>\r\n\t\t\t</div>\r\n\t\t\t<div class="navbar-collapse collapse">\r\n\t\t\t  <ul class="nav navbar-nav navbar-right" id=\'navTabs\'>\r\n\t\t\t\t<li id=\'home\' class="active"><a href="#/home">Home</a></li>\r\n\t\t\t\t<li id=\'videos\'><a href="#/videos">View Videos</a></li>\r\n\t\t\t\t<li id=\'reports\'><a href="#/reports">Reports</a></li> \r\n\t\t\t\t<li><a href="#/login">Logout</a></li>\r\n\t\t\t  </ul>\r\n\t\t\t</div><!--/.nav-collapse -->\r\n      </div>\r\n\t  <div class=\'pageContent row zeroMargin\'>\r\n\t\t<div ng-view=""></div>\r\n\t  </div>\r\n\t  <footer>\r\n\t\t<p class=\'footer\'><strong>&copy; Varsity Media</strong></p>\r\n\t  </footer>\r\n\t</div>\r\n\r\n\r\n</body>\r\n</html>\r\n'
Exception on /login2 [GET]
Traceback (most recent call last):
  File "/Library/Python/2.7/site-packages/flask/app.py", line 1687, in wsgi_app
    response = self.full_dispatch_request()
  File "/Library/Python/2.7/site-packages/flask/app.py", line 1360, in full_dispatch_request
    rv = self.handle_user_exception(e)
  File "/Library/Python/2.7/site-packages/flask/app.py", line 1358, in full_dispatch_request
    rv = self.dispatch_request()
  File "/Library/Python/2.7/site-packages/flask/app.py", line 1344, in dispatch_request
    return self.view_functions[rule.endpoint](**req.view_args)
  File "/Users/asraj/github/vmedia-heroku/app.py", line 35, in index2
    return render_template('index.html')
NameError: global name 'render_template' is not defined
Exception on /login2 [GET]
Traceback (most recent call last):
  File "/Library/Python/2.7/site-packages/flask/app.py", line 1687, in wsgi_app
    response = self.full_dispatch_request()
  File "/Library/Python/2.7/site-packages/flask/app.py", line 1360, in full_dispatch_request
    rv = self.handle_user_exception(e)
  File "/Library/Python/2.7/site-packages/flask/app.py", line 1358, in full_dispatch_request
    rv = self.dispatch_request()
  File "/Library/Python/2.7/site-packages/flask/app.py", line 1344, in dispatch_request
    return self.view_functions[rule.endpoint](**req.view_args)
  File "/Users/asraj/github/vmedia-heroku/app.py", line 35, in index2
    return send_file('index.html')
  File "/Library/Python/2.7/site-packages/flask/helpers.py", line 568, in send_file
    file = open(filename, 'rb')
IOError: [Errno 2] No such file or directory: '/Users/asraj/github/vmedia-heroku/index.html'
Exception on /login2 [GET]
Traceback (most recent call last):
  File "/Library/Python/2.7/site-packages/flask/app.py", line 1687, in wsgi_app
    response = self.full_dispatch_request()
  File "/Library/Python/2.7/site-packages/flask/app.py", line 1360, in full_dispatch_request
    rv = self.handle_user_exception(e)
  File "/Library/Python/2.7/site-packages/flask/app.py", line 1358, in full_dispatch_request
    rv = self.dispatch_request()
  File "/Library/Python/2.7/site-packages/flask/app.py", line 1344, in dispatch_request
    return self.view_functions[rule.endpoint](**req.view_args)
  File "/Users/asraj/github/vmedia-heroku/app.py", line 35, in index2
    return send_file('index.html')
  File "/Library/Python/2.7/site-packages/flask/helpers.py", line 568, in send_file
    file = open(filename, 'rb')
IOError: [Errno 2] No such file or directory: '/Users/asraj/github/vmedia-heroku/index.html'
Exception on /login2 [GET]
Traceback (most recent call last):
  File "/Library/Python/2.7/site-packages/flask/app.py", line 1687, in wsgi_app
    response = self.full_dispatch_request()
  File "/Library/Python/2.7/site-packages/flask/app.py", line 1360, in full_dispatch_request
    rv = self.handle_user_exception(e)
  File "/Library/Python/2.7/site-packages/flask/app.py", line 1358, in full_dispatch_request
    rv = self.dispatch_request()
  File "/Library/Python/2.7/site-packages/flask/app.py", line 1344, in dispatch_request
    return self.view_functions[rule.endpoint](**req.view_args)
  File "/Users/asraj/github/vmedia-heroku/app.py", line 35, in index2
    return render_template('templates/index.html')
NameError: global name 'render_template' is not defined
Exception on /login2 [GET]
Traceback (most recent call last):
  File "/Library/Python/2.7/site-packages/flask/app.py", line 1687, in wsgi_app
    response = self.full_dispatch_request()
  File "/Library/Python/2.7/site-packages/flask/app.py", line 1360, in full_dispatch_request
    rv = self.handle_user_exception(e)
  File "/Library/Python/2.7/site-packages/flask/app.py", line 1358, in full_dispatch_request
    rv = self.dispatch_request()
  File "/Library/Python/2.7/site-packages/flask/app.py", line 1344, in dispatch_request
    return self.view_functions[rule.endpoint](**req.view_args)
  File "/Users/asraj/github/vmedia-heroku/app.py", line 36, in index2
    return render_template('templates/index.html')
NameError: global name 'render_template' is not defined
Exception on /login2 [GET]
Traceback (most recent call last):
  File "/Library/Python/2.7/site-packages/flask/app.py", line 1687, in wsgi_app
    response = self.full_dispatch_request()
  File "/Library/Python/2.7/site-packages/flask/app.py", line 1360, in full_dispatch_request
    rv = self.handle_user_exception(e)
  File "/Library/Python/2.7/site-packages/flask/app.py", line 1358, in full_dispatch_request
    rv = self.dispatch_request()
  File "/Library/Python/2.7/site-packages/flask/app.py", line 1344, in dispatch_request
    return self.view_functions[rule.endpoint](**req.view_args)
  File "/Users/asraj/github/vmedia-heroku/app.py", line 36, in index2
    return render_template('templates/index.html')
NameError: global name 'render_template' is not defined
Exception on /login2 [GET]
Traceback (most recent call last):
  File "/Library/Python/2.7/site-packages/flask/app.py", line 1687, in wsgi_app
    response = self.full_dispatch_request()
  File "/Library/Python/2.7/site-packages/flask/app.py", line 1360, in full_dispatch_request
    rv = self.handle_user_exception(e)
  File "/Library/Python/2.7/site-packages/flask/app.py", line 1358, in full_dispatch_request
    rv = self.dispatch_request()
  File "/Library/Python/2.7/site-packages/flask/app.py", line 1344, in dispatch_request
    return self.view_functions[rule.endpoint](**req.view_args)
  File "/Users/asraj/github/vmedia-heroku/app.py", line 36, in index2
    return render_template('templates/index.html')
NameError: global name 'render_template' is not defined
Exception on /login2 [GET]
Traceback (most recent call last):
  File "/Library/Python/2.7/site-packages/flask/app.py", line 1687, in wsgi_app
    response = self.full_dispatch_request()
  File "/Library/Python/2.7/site-packages/flask/app.py", line 1360, in full_dispatch_request
    rv = self.handle_user_exception(e)
  File "/Library/Python/2.7/site-packages/flask/app.py", line 1358, in full_dispatch_request
    rv = self.dispatch_request()
  File "/Library/Python/2.7/site-packages/flask/app.py", line 1344, in dispatch_request
    return self.view_functions[rule.endpoint](**req.view_args)
  File "/Users/asraj/github/vmedia-heroku/app.py", line 36, in index2
    return render_template('templates/index.html')
NameError: global name 'render_template' is not defined
Exception on /login2 [GET]
Traceback (most recent call last):
  File "/Library/Python/2.7/site-packages/flask/app.py", line 1687, in wsgi_app
    response = self.full_dispatch_request()
  File "/Library/Python/2.7/site-packages/flask/app.py", line 1360, in full_dispatch_request
    rv = self.handle_user_exception(e)
  File "/Library/Python/2.7/site-packages/flask/app.py", line 1358, in full_dispatch_request
    rv = self.dispatch_request()
  File "/Library/Python/2.7/site-packages/flask/app.py", line 1344, in dispatch_request
    return self.view_functions[rule.endpoint](**req.view_args)
  File "/Users/asraj/github/vmedia-heroku/app.py", line 36, in index2
    return render_template('index.html')
NameError: global name 'render_template' is not defined
Exception on /login2 [GET]
Traceback (most recent call last):
  File "/Library/Python/2.7/site-packages/flask/app.py", line 1687, in wsgi_app
    response = self.full_dispatch_request()
  File "/Library/Python/2.7/site-packages/flask/app.py", line 1360, in full_dispatch_request
    rv = self.handle_user_exception(e)
  File "/Library/Python/2.7/site-packages/flask/app.py", line 1358, in full_dispatch_request
    rv = self.dispatch_request()
  File "/Library/Python/2.7/site-packages/flask/app.py", line 1344, in dispatch_request
    return self.view_functions[rule.endpoint](**req.view_args)
  File "/Users/asraj/github/vmedia-heroku/app.py", line 36, in index2
    return render_template('index.html')
NameError: global name 'render_template' is not defined
Exception on /login2 [GET]
Traceback (most recent call last):
  File "/Library/Python/2.7/site-packages/flask/app.py", line 1687, in wsgi_app
    response = self.full_dispatch_request()
  File "/Library/Python/2.7/site-packages/flask/app.py", line 1360, in full_dispatch_request
    rv = self.handle_user_exception(e)
  File "/Library/Python/2.7/site-packages/flask/app.py", line 1358, in full_dispatch_request
    rv = self.dispatch_request()
  File "/Library/Python/2.7/site-packages/flask/app.py", line 1344, in dispatch_request
    return self.view_functions[rule.endpoint](**req.view_args)
  File "/Users/asraj/github/vmedia-heroku/app.py", line 36, in index2
    return render_template('index.html')
NameError: global name 'render_template' is not defined
Exception on /login2 [GET]
Traceback (most recent call last):
  File "/Library/Python/2.7/site-packages/flask/app.py", line 1687, in wsgi_app
    response = self.full_dispatch_request()
  File "/Library/Python/2.7/site-packages/flask/app.py", line 1360, in full_dispatch_request
    rv = self.handle_user_exception(e)
  File "/Library/Python/2.7/site-packages/flask/app.py", line 1358, in full_dispatch_request
    rv = self.dispatch_request()
  File "/Library/Python/2.7/site-packages/flask/app.py", line 1344, in dispatch_request
    return self.view_functions[rule.endpoint](**req.view_args)
  File "/Users/asraj/github/vmedia-heroku/app.py", line 36, in index2
    return render_template('index.html')
NameError: global name 'render_template' is not defined
2013-12-25 00:58:40.259651- /getLabels called
2013-12-25 00:59:45.607245- /getLabels called
Exception on /getLabels [GET]
Traceback (most recent call last):
  File "/Library/Python/2.7/site-packages/flask/app.py", line 1687, in wsgi_app
    response = self.full_dispatch_request()
  File "/Library/Python/2.7/site-packages/flask/app.py", line 1360, in full_dispatch_request
    rv = self.handle_user_exception(e)
  File "/Library/Python/2.7/site-packages/flask/app.py", line 1358, in full_dispatch_request
    rv = self.dispatch_request()
  File "/Library/Python/2.7/site-packages/flask/app.py", line 1344, in dispatch_request
    return self.view_functions[rule.endpoint](**req.view_args)
  File "/Users/asraj/github/vmedia-heroku/app.py", line 232, in getLabels
    for label in Label.select():
  File "/Library/Python/2.7/site-packages/peewee.py", line 1721, in __iter__
    return iter(self.execute())
  File "/Library/Python/2.7/site-packages/peewee.py", line 1714, in execute
    self._qr = ResultWrapper(model_class, self._execute(), query_meta)
  File "/Library/Python/2.7/site-packages/peewee.py", line 1470, in _execute
    return self.database.execute_sql(sql, params, self.require_commit)
  File "/Library/Python/2.7/site-packages/peewee.py", line 1885, in execute_sql
    return self.sql_error_handler(exc, sql, params, require_commit)
  File "/Library/Python/2.7/site-packages/peewee.py", line 1871, in sql_error_handler
    raise exception
OperationalError: (2006, 'MySQL server has gone away')
2013-12-25 01:18:21.490858- /getLabels called
Exception on /getLabels [GET]
Traceback (most recent call last):
  File "/Library/Python/2.7/site-packages/flask/app.py", line 1687, in wsgi_app
    response = self.full_dispatch_request()
  File "/Library/Python/2.7/site-packages/flask/app.py", line 1360, in full_dispatch_request
    rv = self.handle_user_exception(e)
  File "/Library/Python/2.7/site-packages/flask/app.py", line 1358, in full_dispatch_request
    rv = self.dispatch_request()
  File "/Library/Python/2.7/site-packages/flask/app.py", line 1344, in dispatch_request
    return self.view_functions[rule.endpoint](**req.view_args)
  File "/Users/asraj/github/vmedia-heroku/app.py", line 232, in getLabels
    for label in Label.select():
  File "/Library/Python/2.7/site-packages/peewee.py", line 1721, in __iter__
    return iter(self.execute())
  File "/Library/Python/2.7/site-packages/peewee.py", line 1714, in execute
    self._qr = ResultWrapper(model_class, self._execute(), query_meta)
  File "/Library/Python/2.7/site-packages/peewee.py", line 1470, in _execute
    return self.database.execute_sql(sql, params, self.require_commit)
  File "/Library/Python/2.7/site-packages/peewee.py", line 1885, in execute_sql
    return self.sql_error_handler(exc, sql, params, require_commit)
  File "/Library/Python/2.7/site-packages/peewee.py", line 1871, in sql_error_handler
    raise exception
OperationalError: (2006, 'MySQL server has gone away')
2013-12-25 01:20:01.822235- /getLabels called
2013-12-25 01:31:24.863362- /getLabels called
Exception on /getLabels [GET]
Traceback (most recent call last):
  File "/Users/asraj/github/vmedia-heroku/venv/lib/python2.7/site-packages/flask/app.py", line 1687, in wsgi_app
    response = self.full_dispatch_request()
  File "/Users/asraj/github/vmedia-heroku/venv/lib/python2.7/site-packages/flask/app.py", line 1360, in full_dispatch_request
    rv = self.handle_user_exception(e)
  File "/Users/asraj/github/vmedia-heroku/venv/lib/python2.7/site-packages/flask/app.py", line 1358, in full_dispatch_request
    rv = self.dispatch_request()
  File "/Users/asraj/github/vmedia-heroku/venv/lib/python2.7/site-packages/flask/app.py", line 1344, in dispatch_request
    return self.view_functions[rule.endpoint](**req.view_args)
  File "/Users/asraj/github/vmedia-heroku/app.py", line 232, in getLabels
    for label in Label.select():
  File "/Users/asraj/github/vmedia-heroku/venv/lib/python2.7/site-packages/peewee.py", line 1378, in __iter__
    return iter(self.execute())
  File "/Users/asraj/github/vmedia-heroku/venv/lib/python2.7/site-packages/peewee.py", line 1371, in execute
    self._qr = QueryResultWrapper(self.model_class, self.database.execute(self), query_meta)
  File "/Users/asraj/github/vmedia-heroku/venv/lib/python2.7/site-packages/peewee.py", line 1506, in execute
    return self.execute_sql(sql, params, query.require_commit)
  File "/Users/asraj/github/vmedia-heroku/venv/lib/python2.7/site-packages/peewee.py", line 1510, in execute_sql
    res = cursor.execute(sql, params or ())
  File "/Users/asraj/github/vmedia-heroku/venv/lib/python2.7/site-packages/MySQLdb/cursors.py", line 202, in execute
    self.errorhandler(self, exc, value)
  File "/Users/asraj/github/vmedia-heroku/venv/lib/python2.7/site-packages/MySQLdb/connections.py", line 36, in defaulterrorhandler
    raise errorclass, errorvalue
OperationalError: (2006, 'MySQL server has gone away')
2013-12-25 01:31:48.123262- /getLabels called
Exception on /getLabels [GET]
Traceback (most recent call last):
  File "/Users/asraj/github/vmedia-heroku/venv/lib/python2.7/site-packages/flask/app.py", line 1687, in wsgi_app
    response = self.full_dispatch_request()
  File "/Users/asraj/github/vmedia-heroku/venv/lib/python2.7/site-packages/flask/app.py", line 1360, in full_dispatch_request
    rv = self.handle_user_exception(e)
  File "/Users/asraj/github/vmedia-heroku/venv/lib/python2.7/site-packages/flask/app.py", line 1358, in full_dispatch_request
    rv = self.dispatch_request()
  File "/Users/asraj/github/vmedia-heroku/venv/lib/python2.7/site-packages/flask/app.py", line 1344, in dispatch_request
    return self.view_functions[rule.endpoint](**req.view_args)
  File "/Users/asraj/github/vmedia-heroku/app.py", line 232, in getLabels
    for label in Label.select():
  File "/Users/asraj/github/vmedia-heroku/venv/lib/python2.7/site-packages/peewee.py", line 1378, in __iter__
    return iter(self.execute())
  File "/Users/asraj/github/vmedia-heroku/venv/lib/python2.7/site-packages/peewee.py", line 1371, in execute
    self._qr = QueryResultWrapper(self.model_class, self.database.execute(self), query_meta)
  File "/Users/asraj/github/vmedia-heroku/venv/lib/python2.7/site-packages/peewee.py", line 1506, in execute
    return self.execute_sql(sql, params, query.require_commit)
  File "/Users/asraj/github/vmedia-heroku/venv/lib/python2.7/site-packages/peewee.py", line 1510, in execute_sql
    res = cursor.execute(sql, params or ())
  File "/Users/asraj/github/vmedia-heroku/venv/lib/python2.7/site-packages/MySQLdb/cursors.py", line 202, in execute
    self.errorhandler(self, exc, value)
  File "/Users/asraj/github/vmedia-heroku/venv/lib/python2.7/site-packages/MySQLdb/connections.py", line 36, in defaulterrorhandler
    raise errorclass, errorvalue
OperationalError: (2006, 'MySQL server has gone away')
2013-12-25 01:41:25.093848- /getLabels called
Exception on /getLabels [GET]
Traceback (most recent call last):
  File "/Users/asraj/github/vmedia-heroku/venv/lib/python2.7/site-packages/flask/app.py", line 1687, in wsgi_app
    response = self.full_dispatch_request()
  File "/Users/asraj/github/vmedia-heroku/venv/lib/python2.7/site-packages/flask/app.py", line 1360, in full_dispatch_request
    rv = self.handle_user_exception(e)
  File "/Users/asraj/github/vmedia-heroku/venv/lib/python2.7/site-packages/flask/app.py", line 1358, in full_dispatch_request
    rv = self.dispatch_request()
  File "/Users/asraj/github/vmedia-heroku/venv/lib/python2.7/site-packages/flask/app.py", line 1344, in dispatch_request
    return self.view_functions[rule.endpoint](**req.view_args)
  File "/Users/asraj/github/vmedia-heroku/app.py", line 232, in getLabels
    for label in Label.select():
  File "/Users/asraj/github/vmedia-heroku/venv/lib/python2.7/site-packages/peewee.py", line 1378, in __iter__
    return iter(self.execute())
  File "/Users/asraj/github/vmedia-heroku/venv/lib/python2.7/site-packages/peewee.py", line 1371, in execute
    self._qr = QueryResultWrapper(self.model_class, self.database.execute(self), query_meta)
  File "/Users/asraj/github/vmedia-heroku/venv/lib/python2.7/site-packages/peewee.py", line 1506, in execute
    return self.execute_sql(sql, params, query.require_commit)
  File "/Users/asraj/github/vmedia-heroku/venv/lib/python2.7/site-packages/peewee.py", line 1510, in execute_sql
    res = cursor.execute(sql, params or ())
  File "/Users/asraj/github/vmedia-heroku/venv/lib/python2.7/site-packages/MySQLdb/cursors.py", line 202, in execute
    self.errorhandler(self, exc, value)
  File "/Users/asraj/github/vmedia-heroku/venv/lib/python2.7/site-packages/MySQLdb/connections.py", line 36, in defaulterrorhandler
    raise errorclass, errorvalue
OperationalError: (2006, 'MySQL server has gone away')
2013-12-25 01:41:51.592325- /getLabels called
2013-12-25 01:58:21.615597- /getLabels called
2013-12-25 02:02:00.529674- /getLabels called
Exception on /getLabels [GET]
Traceback (most recent call last):
  File "/Users/asraj/github/vmedia-heroku/venv/lib/python2.7/site-packages/flask/app.py", line 1687, in wsgi_app
    response = self.full_dispatch_request()
  File "/Users/asraj/github/vmedia-heroku/venv/lib/python2.7/site-packages/flask/app.py", line 1360, in full_dispatch_request
    rv = self.handle_user_exception(e)
  File "/Users/asraj/github/vmedia-heroku/venv/lib/python2.7/site-packages/flask/app.py", line 1358, in full_dispatch_request
    rv = self.dispatch_request()
  File "/Users/asraj/github/vmedia-heroku/venv/lib/python2.7/site-packages/flask/app.py", line 1344, in dispatch_request
    return self.view_functions[rule.endpoint](**req.view_args)
  File "/Users/asraj/github/vmedia-heroku/app.py", line 232, in getLabels
    for label in Label.select():
  File "/Users/asraj/github/vmedia-heroku/venv/lib/python2.7/site-packages/peewee.py", line 1378, in __iter__
    return iter(self.execute())
  File "/Users/asraj/github/vmedia-heroku/venv/lib/python2.7/site-packages/peewee.py", line 1371, in execute
    self._qr = QueryResultWrapper(self.model_class, self.database.execute(self), query_meta)
  File "/Users/asraj/github/vmedia-heroku/venv/lib/python2.7/site-packages/peewee.py", line 1506, in execute
    return self.execute_sql(sql, params, query.require_commit)
  File "/Users/asraj/github/vmedia-heroku/venv/lib/python2.7/site-packages/peewee.py", line 1510, in execute_sql
    res = cursor.execute(sql, params or ())
  File "/Users/asraj/github/vmedia-heroku/venv/lib/python2.7/site-packages/MySQLdb/cursors.py", line 202, in execute
    self.errorhandler(self, exc, value)
  File "/Users/asraj/github/vmedia-heroku/venv/lib/python2.7/site-packages/MySQLdb/connections.py", line 36, in defaulterrorhandler
    raise errorclass, errorvalue
OperationalError: (2006, 'MySQL server has gone away')
2013-12-25 12:47:21.928563- /getLabels called
Exception on /saveLabel [GET]
Traceback (most recent call last):
  File "/Users/asraj/github/vmedia-heroku/venv/lib/python2.7/site-packages/flask/app.py", line 1687, in wsgi_app
    response = self.full_dispatch_request()
  File "/Users/asraj/github/vmedia-heroku/venv/lib/python2.7/site-packages/flask/app.py", line 1360, in full_dispatch_request
    rv = self.handle_user_exception(e)
  File "/Users/asraj/github/vmedia-heroku/venv/lib/python2.7/site-packages/flask/app.py", line 1358, in full_dispatch_request
    rv = self.dispatch_request()
  File "/Users/asraj/github/vmedia-heroku/venv/lib/python2.7/site-packages/flask/app.py", line 1344, in dispatch_request
    return self.view_functions[rule.endpoint](**req.view_args)
  File "/Users/asraj/github/vmedia-heroku/app.py", line 221, in saveLabel
    label=record["label"]
  File "/Users/asraj/github/vmedia-heroku/venv/lib/python2.7/site-packages/peewee.py", line 1921, in create
    inst.save(force_insert=True)
  File "/Users/asraj/github/vmedia-heroku/venv/lib/python2.7/site-packages/peewee.py", line 1997, in save
    new_pk = insert.execute()
  File "/Users/asraj/github/vmedia-heroku/venv/lib/python2.7/site-packages/peewee.py", line 1419, in execute
    result = self.database.execute(self)
  File "/Users/asraj/github/vmedia-heroku/venv/lib/python2.7/site-packages/peewee.py", line 1506, in execute
    return self.execute_sql(sql, params, query.require_commit)
  File "/Users/asraj/github/vmedia-heroku/venv/lib/python2.7/site-packages/peewee.py", line 1510, in execute_sql
    res = cursor.execute(sql, params or ())
  File "/Users/asraj/github/vmedia-heroku/venv/lib/python2.7/site-packages/MySQLdb/cursors.py", line 202, in execute
    self.errorhandler(self, exc, value)
  File "/Users/asraj/github/vmedia-heroku/venv/lib/python2.7/site-packages/MySQLdb/connections.py", line 36, in defaulterrorhandler
    raise errorclass, errorvalue
OperationalError: (2013, 'Lost connection to MySQL server during query')
2013-12-25 16:44:28.622185- /getLabels called
2013-12-25 16:44:57.505872- /getLabels called
2013-12-25 17:01:33.863422- /getLabels called
Exception on /getLabels [GET]
Traceback (most recent call last):
  File "/Library/Python/2.7/site-packages/flask/app.py", line 1687, in wsgi_app
    response = self.full_dispatch_request()
  File "/Library/Python/2.7/site-packages/flask/app.py", line 1360, in full_dispatch_request
    rv = self.handle_user_exception(e)
  File "/Library/Python/2.7/site-packages/flask/app.py", line 1358, in full_dispatch_request
    rv = self.dispatch_request()
  File "/Library/Python/2.7/site-packages/flask/app.py", line 1344, in dispatch_request
    return self.view_functions[rule.endpoint](**req.view_args)
  File "/Users/asraj/github/vmedia-heroku/app.py", line 232, in getLabels
    for label in Label.select():
  File "/Library/Python/2.7/site-packages/peewee.py", line 1721, in __iter__
    return iter(self.execute())
  File "/Library/Python/2.7/site-packages/peewee.py", line 1714, in execute
    self._qr = ResultWrapper(model_class, self._execute(), query_meta)
  File "/Library/Python/2.7/site-packages/peewee.py", line 1470, in _execute
    return self.database.execute_sql(sql, params, self.require_commit)
  File "/Library/Python/2.7/site-packages/peewee.py", line 1885, in execute_sql
    return self.sql_error_handler(exc, sql, params, require_commit)
  File "/Library/Python/2.7/site-packages/peewee.py", line 1871, in sql_error_handler
    raise exception
OperationalError: (2006, 'MySQL server has gone away')
2013-12-25 17:03:14.178151- /getLabels called
2013-12-25 17:15:36.795566- /getLabels called
2013-12-25 17:23:06.901828- /getLabels called
2013-12-25 17:23:53.516793- /getLabels called
2013-12-25 17:25:26.586481- /getLabels called
2013-12-25 17:33:34.675395- /getLabels called
Exception on /getVideos [GET]
Traceback (most recent call last):
  File "/Library/Python/2.7/site-packages/flask/app.py", line 1687, in wsgi_app
    response = self.full_dispatch_request()
  File "/Library/Python/2.7/site-packages/flask/app.py", line 1360, in full_dispatch_request
    rv = self.handle_user_exception(e)
  File "/Library/Python/2.7/site-packages/flask/app.py", line 1358, in full_dispatch_request
    rv = self.dispatch_request()
  File "/Library/Python/2.7/site-packages/flask/app.py", line 1344, in dispatch_request
    return self.view_functions[rule.endpoint](**req.view_args)
  File "/Users/asraj/github/vmedia-heroku/app.py", line 216, in getVideos
    responsejson.append({'result':'OK', 'videos':videos})
NameError: global name 'responsejson' is not defined
2013-12-25 17:34:24.144163- /getLabels called
Exception on /getVideos [GET]
Traceback (most recent call last):
  File "/Library/Python/2.7/site-packages/flask/app.py", line 1687, in wsgi_app
    response = self.full_dispatch_request()
  File "/Library/Python/2.7/site-packages/flask/app.py", line 1360, in full_dispatch_request
    rv = self.handle_user_exception(e)
  File "/Library/Python/2.7/site-packages/flask/app.py", line 1358, in full_dispatch_request
    rv = self.dispatch_request()
  File "/Library/Python/2.7/site-packages/flask/app.py", line 1344, in dispatch_request
    return self.view_functions[rule.endpoint](**req.view_args)
  File "/Users/asraj/github/vmedia-heroku/app.py", line 216, in getVideos
    responsejson.append({'result':'OK', 'videos':videos})
NameError: global name 'responsejson' is not defined
2013-12-25 17:36:06.671468- /getLabels called
Exception on /getLabels [GET]
Traceback (most recent call last):
  File "/Library/Python/2.7/site-packages/flask/app.py", line 1687, in wsgi_app
    response = self.full_dispatch_request()
  File "/Library/Python/2.7/site-packages/flask/app.py", line 1360, in full_dispatch_request
    rv = self.handle_user_exception(e)
  File "/Library/Python/2.7/site-packages/flask/app.py", line 1358, in full_dispatch_request
    rv = self.dispatch_request()
  File "/Library/Python/2.7/site-packages/flask/app.py", line 1344, in dispatch_request
    return self.view_functions[rule.endpoint](**req.view_args)
  File "/Users/asraj/github/vmedia-heroku/app.py", line 273, in getLabels
    for label in Label.select():
  File "/Library/Python/2.7/site-packages/peewee.py", line 1721, in __iter__
    return iter(self.execute())
  File "/Library/Python/2.7/site-packages/peewee.py", line 1714, in execute
    self._qr = ResultWrapper(model_class, self._execute(), query_meta)
  File "/Library/Python/2.7/site-packages/peewee.py", line 1470, in _execute
    return self.database.execute_sql(sql, params, self.require_commit)
  File "/Library/Python/2.7/site-packages/peewee.py", line 1885, in execute_sql
    return self.sql_error_handler(exc, sql, params, require_commit)
  File "/Library/Python/2.7/site-packages/peewee.py", line 1871, in sql_error_handler
    raise exception
OperationalError: (2006, 'MySQL server has gone away')
Exception on /getVideos [GET]
Traceback (most recent call last):
  File "/Library/Python/2.7/site-packages/flask/app.py", line 1687, in wsgi_app
    response = self.full_dispatch_request()
  File "/Library/Python/2.7/site-packages/flask/app.py", line 1360, in full_dispatch_request
    rv = self.handle_user_exception(e)
  File "/Library/Python/2.7/site-packages/flask/app.py", line 1358, in full_dispatch_request
    rv = self.dispatch_request()
  File "/Library/Python/2.7/site-packages/flask/app.py", line 1344, in dispatch_request
    return self.view_functions[rule.endpoint](**req.view_args)
  File "/Users/asraj/github/vmedia-heroku/app.py", line 209, in getVideos
    for record in Video.raw("select * from vm_videos where status='N'"):
  File "/Library/Python/2.7/site-packages/peewee.py", line 1527, in __iter__
    return iter(self.execute())
  File "/Library/Python/2.7/site-packages/peewee.py", line 1523, in execute
    self._qr = ResultWrapper(self.model_class, self._execute(), None)
  File "/Library/Python/2.7/site-packages/peewee.py", line 1470, in _execute
    return self.database.execute_sql(sql, params, self.require_commit)
  File "/Library/Python/2.7/site-packages/peewee.py", line 1885, in execute_sql
    return self.sql_error_handler(exc, sql, params, require_commit)
  File "/Library/Python/2.7/site-packages/peewee.py", line 1871, in sql_error_handler
    raise exception
OperationalError: (2006, 'MySQL server has gone away')
2013-12-25 17:36:25.213430- /getLabels called
Exception on /getLabels [GET]
Traceback (most recent call last):
  File "/Library/Python/2.7/site-packages/flask/app.py", line 1687, in wsgi_app
    response = self.full_dispatch_request()
  File "/Library/Python/2.7/site-packages/flask/app.py", line 1360, in full_dispatch_request
    rv = self.handle_user_exception(e)
  File "/Library/Python/2.7/site-packages/flask/app.py", line 1358, in full_dispatch_request
    rv = self.dispatch_request()
  File "/Library/Python/2.7/site-packages/flask/app.py", line 1344, in dispatch_request
    return self.view_functions[rule.endpoint](**req.view_args)
  File "/Users/asraj/github/vmedia-heroku/app.py", line 273, in getLabels
    for label in Label.select():
  File "/Library/Python/2.7/site-packages/peewee.py", line 1721, in __iter__
    return iter(self.execute())
  File "/Library/Python/2.7/site-packages/peewee.py", line 1714, in execute
    self._qr = ResultWrapper(model_class, self._execute(), query_meta)
  File "/Library/Python/2.7/site-packages/peewee.py", line 1470, in _execute
    return self.database.execute_sql(sql, params, self.require_commit)
  File "/Library/Python/2.7/site-packages/peewee.py", line 1885, in execute_sql
    return self.sql_error_handler(exc, sql, params, require_commit)
  File "/Library/Python/2.7/site-packages/peewee.py", line 1871, in sql_error_handler
    raise exception
OperationalError: (2006, 'MySQL server has gone away')
2013-12-25 17:37:07.812809- /getLabels called
2013-12-25 17:44:24.439203- /getLabels called
2013-12-25 17:48:06.655707- /getLabels called
2013-12-25 17:48:28.387224- /getLabels called
2013-12-25 17:48:55.657995- /getLabels called
2013-12-25 17:59:14.112710- /getLabels called
Exception on /getVideos [GET]
Traceback (most recent call last):
  File "/Library/Python/2.7/site-packages/flask/app.py", line 1687, in wsgi_app
    response = self.full_dispatch_request()
  File "/Library/Python/2.7/site-packages/flask/app.py", line 1360, in full_dispatch_request
    rv = self.handle_user_exception(e)
  File "/Library/Python/2.7/site-packages/flask/app.py", line 1358, in full_dispatch_request
    rv = self.dispatch_request()
  File "/Library/Python/2.7/site-packages/flask/app.py", line 1344, in dispatch_request
    return self.view_functions[rule.endpoint](**req.view_args)
  File "/Users/asraj/github/vmedia-heroku/app.py", line 216, in getVideos
    responsejson.append({'result':'OK', 'videos':json.dumps(videos)})
NameError: global name 'responsejson' is not defined
2013-12-25 18:00:02.903182- /getLabels called
Exception on /getVideos [GET]
Traceback (most recent call last):
  File "/Library/Python/2.7/site-packages/flask/app.py", line 1687, in wsgi_app
    response = self.full_dispatch_request()
  File "/Library/Python/2.7/site-packages/flask/app.py", line 1360, in full_dispatch_request
    rv = self.handle_user_exception(e)
  File "/Library/Python/2.7/site-packages/flask/app.py", line 1358, in full_dispatch_request
    rv = self.dispatch_request()
  File "/Library/Python/2.7/site-packages/flask/app.py", line 1344, in dispatch_request
    return self.view_functions[rule.endpoint](**req.view_args)
  File "/Users/asraj/github/vmedia-heroku/app.py", line 216, in getVideos
    responsejson.append({'result':'OK', 'videos':json.loads(videos)})
NameError: global name 'responsejson' is not defined
2013-12-25 18:00:29.464477- /getLabels called
Exception on /getVideos [GET]
Traceback (most recent call last):
  File "/Library/Python/2.7/site-packages/flask/app.py", line 1687, in wsgi_app
    response = self.full_dispatch_request()
  File "/Library/Python/2.7/site-packages/flask/app.py", line 1360, in full_dispatch_request
    rv = self.handle_user_exception(e)
  File "/Library/Python/2.7/site-packages/flask/app.py", line 1358, in full_dispatch_request
    rv = self.dispatch_request()
  File "/Library/Python/2.7/site-packages/flask/app.py", line 1344, in dispatch_request
    return self.view_functions[rule.endpoint](**req.view_args)
  File "/Users/asraj/github/vmedia-heroku/app.py", line 216, in getVideos
    responsejson.append({'result':'OK', 'videos':json.loads(videos)})
NameError: global name 'responsejson' is not defined
2013-12-25 18:01:21.746814- /getLabels called
Exception on /getVideos [GET]
Traceback (most recent call last):
  File "/Library/Python/2.7/site-packages/flask/app.py", line 1687, in wsgi_app
    response = self.full_dispatch_request()
  File "/Library/Python/2.7/site-packages/flask/app.py", line 1360, in full_dispatch_request
    rv = self.handle_user_exception(e)
  File "/Library/Python/2.7/site-packages/flask/app.py", line 1358, in full_dispatch_request
    rv = self.dispatch_request()
  File "/Library/Python/2.7/site-packages/flask/app.py", line 1344, in dispatch_request
    return self.view_functions[rule.endpoint](**req.view_args)
  File "/Users/asraj/github/vmedia-heroku/app.py", line 216, in getVideos
    responsejson.append({'result':'OK', 'videos':str(videos)})
NameError: global name 'responsejson' is not defined
2013-12-25 23:09:25.772171- /getLabels called
2013-12-25 23:11:44.384951- /getLabels called
Exception on /getLabels [GET]
Traceback (most recent call last):
  File "/Library/Python/2.7/site-packages/flask/app.py", line 1687, in wsgi_app
    response = self.full_dispatch_request()
  File "/Library/Python/2.7/site-packages/flask/app.py", line 1360, in full_dispatch_request
    rv = self.handle_user_exception(e)
  File "/Library/Python/2.7/site-packages/flask/app.py", line 1358, in full_dispatch_request
    rv = self.dispatch_request()
  File "/Library/Python/2.7/site-packages/flask/app.py", line 1344, in dispatch_request
    return self.view_functions[rule.endpoint](**req.view_args)
  File "/Users/asraj/github/vmedia-heroku/app.py", line 273, in getLabels
    for label in Label.select():
  File "/Library/Python/2.7/site-packages/peewee.py", line 1721, in __iter__
    return iter(self.execute())
  File "/Library/Python/2.7/site-packages/peewee.py", line 1714, in execute
    self._qr = ResultWrapper(model_class, self._execute(), query_meta)
  File "/Library/Python/2.7/site-packages/peewee.py", line 1470, in _execute
    return self.database.execute_sql(sql, params, self.require_commit)
  File "/Library/Python/2.7/site-packages/peewee.py", line 1885, in execute_sql
    return self.sql_error_handler(exc, sql, params, require_commit)
  File "/Library/Python/2.7/site-packages/peewee.py", line 1871, in sql_error_handler
    raise exception
OperationalError: (2006, 'MySQL server has gone away')
Exception on /getVideos [GET]
Traceback (most recent call last):
  File "/Library/Python/2.7/site-packages/flask/app.py", line 1687, in wsgi_app
    response = self.full_dispatch_request()
  File "/Library/Python/2.7/site-packages/flask/app.py", line 1360, in full_dispatch_request
    rv = self.handle_user_exception(e)
  File "/Library/Python/2.7/site-packages/flask/app.py", line 1358, in full_dispatch_request
    rv = self.dispatch_request()
  File "/Library/Python/2.7/site-packages/flask/app.py", line 1344, in dispatch_request
    return self.view_functions[rule.endpoint](**req.view_args)
  File "/Users/asraj/github/vmedia-heroku/app.py", line 209, in getVideos
    for record in Video.raw("select * from vm_videos where status='N'"):
  File "/Library/Python/2.7/site-packages/peewee.py", line 1527, in __iter__
    return iter(self.execute())
  File "/Library/Python/2.7/site-packages/peewee.py", line 1523, in execute
    self._qr = ResultWrapper(self.model_class, self._execute(), None)
  File "/Library/Python/2.7/site-packages/peewee.py", line 1470, in _execute
    return self.database.execute_sql(sql, params, self.require_commit)
  File "/Library/Python/2.7/site-packages/peewee.py", line 1885, in execute_sql
    return self.sql_error_handler(exc, sql, params, require_commit)
  File "/Library/Python/2.7/site-packages/peewee.py", line 1871, in sql_error_handler
    raise exception
OperationalError: (2006, 'MySQL server has gone away')
2013-12-25 23:11:44.426564- /getLabels called
Exception on /getLabels [GET]
Traceback (most recent call last):
  File "/Library/Python/2.7/site-packages/flask/app.py", line 1687, in wsgi_app
    response = self.full_dispatch_request()
  File "/Library/Python/2.7/site-packages/flask/app.py", line 1360, in full_dispatch_request
    rv = self.handle_user_exception(e)
  File "/Library/Python/2.7/site-packages/flask/app.py", line 1358, in full_dispatch_request
    rv = self.dispatch_request()
  File "/Library/Python/2.7/site-packages/flask/app.py", line 1344, in dispatch_request
    return self.view_functions[rule.endpoint](**req.view_args)
  File "/Users/asraj/github/vmedia-heroku/app.py", line 273, in getLabels
    for label in Label.select():
  File "/Library/Python/2.7/site-packages/peewee.py", line 1721, in __iter__
    return iter(self.execute())
  File "/Library/Python/2.7/site-packages/peewee.py", line 1714, in execute
    self._qr = ResultWrapper(model_class, self._execute(), query_meta)
  File "/Library/Python/2.7/site-packages/peewee.py", line 1470, in _execute
    return self.database.execute_sql(sql, params, self.require_commit)
  File "/Library/Python/2.7/site-packages/peewee.py", line 1885, in execute_sql
    return self.sql_error_handler(exc, sql, params, require_commit)
  File "/Library/Python/2.7/site-packages/peewee.py", line 1871, in sql_error_handler
    raise exception
OperationalError: (2006, 'MySQL server has gone away')
Exception on /getVideos [GET]
Traceback (most recent call last):
  File "/Library/Python/2.7/site-packages/flask/app.py", line 1687, in wsgi_app
    response = self.full_dispatch_request()
  File "/Library/Python/2.7/site-packages/flask/app.py", line 1360, in full_dispatch_request
    rv = self.handle_user_exception(e)
  File "/Library/Python/2.7/site-packages/flask/app.py", line 1358, in full_dispatch_request
    rv = self.dispatch_request()
  File "/Library/Python/2.7/site-packages/flask/app.py", line 1344, in dispatch_request
    return self.view_functions[rule.endpoint](**req.view_args)
  File "/Users/asraj/github/vmedia-heroku/app.py", line 209, in getVideos
    for record in Video.raw("select * from vm_videos where status='N'"):
  File "/Library/Python/2.7/site-packages/peewee.py", line 1527, in __iter__
    return iter(self.execute())
  File "/Library/Python/2.7/site-packages/peewee.py", line 1523, in execute
    self._qr = ResultWrapper(self.model_class, self._execute(), None)
  File "/Library/Python/2.7/site-packages/peewee.py", line 1470, in _execute
    return self.database.execute_sql(sql, params, self.require_commit)
  File "/Library/Python/2.7/site-packages/peewee.py", line 1885, in execute_sql
    return self.sql_error_handler(exc, sql, params, require_commit)
  File "/Library/Python/2.7/site-packages/peewee.py", line 1871, in sql_error_handler
    raise exception
OperationalError: (2006, 'MySQL server has gone away')
2013-12-25 23:13:15.356661- /getLabels called
2013-12-25 23:16:36.377805- /getLabels called
Exception on /getLabels [GET]
Traceback (most recent call last):
  File "/Library/Python/2.7/site-packages/flask/app.py", line 1687, in wsgi_app
    response = self.full_dispatch_request()
  File "/Library/Python/2.7/site-packages/flask/app.py", line 1360, in full_dispatch_request
    rv = self.handle_user_exception(e)
  File "/Library/Python/2.7/site-packages/flask/app.py", line 1358, in full_dispatch_request
    rv = self.dispatch_request()
  File "/Library/Python/2.7/site-packages/flask/app.py", line 1344, in dispatch_request
    return self.view_functions[rule.endpoint](**req.view_args)
  File "/Users/asraj/github/vmedia-heroku/app.py", line 273, in getLabels
    for label in Label.select():
  File "/Library/Python/2.7/site-packages/peewee.py", line 1721, in __iter__
    return iter(self.execute())
  File "/Library/Python/2.7/site-packages/peewee.py", line 1714, in execute
    self._qr = ResultWrapper(model_class, self._execute(), query_meta)
  File "/Library/Python/2.7/site-packages/peewee.py", line 1470, in _execute
    return self.database.execute_sql(sql, params, self.require_commit)
  File "/Library/Python/2.7/site-packages/peewee.py", line 1885, in execute_sql
    return self.sql_error_handler(exc, sql, params, require_commit)
  File "/Library/Python/2.7/site-packages/peewee.py", line 1871, in sql_error_handler
    raise exception
OperationalError: (2006, 'MySQL server has gone away')
Exception on /getVideos [GET]
Traceback (most recent call last):
  File "/Library/Python/2.7/site-packages/flask/app.py", line 1687, in wsgi_app
    response = self.full_dispatch_request()
  File "/Library/Python/2.7/site-packages/flask/app.py", line 1360, in full_dispatch_request
    rv = self.handle_user_exception(e)
  File "/Library/Python/2.7/site-packages/flask/app.py", line 1358, in full_dispatch_request
    rv = self.dispatch_request()
  File "/Library/Python/2.7/site-packages/flask/app.py", line 1344, in dispatch_request
    return self.view_functions[rule.endpoint](**req.view_args)
  File "/Users/asraj/github/vmedia-heroku/app.py", line 209, in getVideos
    for record in Video.raw("select * from vm_videos where status='N'"):
  File "/Library/Python/2.7/site-packages/peewee.py", line 1527, in __iter__
    return iter(self.execute())
  File "/Library/Python/2.7/site-packages/peewee.py", line 1523, in execute
    self._qr = ResultWrapper(self.model_class, self._execute(), None)
  File "/Library/Python/2.7/site-packages/peewee.py", line 1470, in _execute
    return self.database.execute_sql(sql, params, self.require_commit)
  File "/Library/Python/2.7/site-packages/peewee.py", line 1885, in execute_sql
    return self.sql_error_handler(exc, sql, params, require_commit)
  File "/Library/Python/2.7/site-packages/peewee.py", line 1871, in sql_error_handler
    raise exception
OperationalError: (2006, 'MySQL server has gone away')
2013-12-25 23:26:02.326979- /getLabels called
2013-12-25 23:30:23.235740- /getLabels called
2013-12-26 00:48:12.077506- /getLabels called
Exception on /getLabels [GET]
Traceback (most recent call last):
  File "/Library/Python/2.7/site-packages/flask/app.py", line 1687, in wsgi_app
    response = self.full_dispatch_request()
  File "/Library/Python/2.7/site-packages/flask/app.py", line 1360, in full_dispatch_request
    rv = self.handle_user_exception(e)
  File "/Library/Python/2.7/site-packages/flask/app.py", line 1358, in full_dispatch_request
    rv = self.dispatch_request()
  File "/Library/Python/2.7/site-packages/flask/app.py", line 1344, in dispatch_request
    return self.view_functions[rule.endpoint](**req.view_args)
  File "/Users/asraj/github/vmedia-heroku/app.py", line 273, in getLabels
    for label in Label.select():
  File "/Library/Python/2.7/site-packages/peewee.py", line 1721, in __iter__
    return iter(self.execute())
  File "/Library/Python/2.7/site-packages/peewee.py", line 1714, in execute
    self._qr = ResultWrapper(model_class, self._execute(), query_meta)
  File "/Library/Python/2.7/site-packages/peewee.py", line 1470, in _execute
    return self.database.execute_sql(sql, params, self.require_commit)
  File "/Library/Python/2.7/site-packages/peewee.py", line 1885, in execute_sql
    return self.sql_error_handler(exc, sql, params, require_commit)
  File "/Library/Python/2.7/site-packages/peewee.py", line 1871, in sql_error_handler
    raise exception
OperationalError: (2006, 'MySQL server has gone away')
Exception on /getVideos [GET]
Traceback (most recent call last):
  File "/Library/Python/2.7/site-packages/flask/app.py", line 1687, in wsgi_app
    response = self.full_dispatch_request()
  File "/Library/Python/2.7/site-packages/flask/app.py", line 1360, in full_dispatch_request
    rv = self.handle_user_exception(e)
  File "/Library/Python/2.7/site-packages/flask/app.py", line 1358, in full_dispatch_request
    rv = self.dispatch_request()
  File "/Library/Python/2.7/site-packages/flask/app.py", line 1344, in dispatch_request
    return self.view_functions[rule.endpoint](**req.view_args)
  File "/Users/asraj/github/vmedia-heroku/app.py", line 209, in getVideos
    for record in Video.raw("select * from vm_videos where status='N'"):
  File "/Library/Python/2.7/site-packages/peewee.py", line 1527, in __iter__
    return iter(self.execute())
  File "/Library/Python/2.7/site-packages/peewee.py", line 1523, in execute
    self._qr = ResultWrapper(self.model_class, self._execute(), None)
  File "/Library/Python/2.7/site-packages/peewee.py", line 1470, in _execute
    return self.database.execute_sql(sql, params, self.require_commit)
  File "/Library/Python/2.7/site-packages/peewee.py", line 1885, in execute_sql
    return self.sql_error_handler(exc, sql, params, require_commit)
  File "/Library/Python/2.7/site-packages/peewee.py", line 1871, in sql_error_handler
    raise exception
OperationalError: (2006, 'MySQL server has gone away')
2013-12-26 00:48:17.682450- /getLabels called
Exception on /getLabels [GET]
Traceback (most recent call last):
  File "/Library/Python/2.7/site-packages/flask/app.py", line 1687, in wsgi_app
    response = self.full_dispatch_request()
  File "/Library/Python/2.7/site-packages/flask/app.py", line 1360, in full_dispatch_request
    rv = self.handle_user_exception(e)
  File "/Library/Python/2.7/site-packages/flask/app.py", line 1358, in full_dispatch_request
    rv = self.dispatch_request()
  File "/Library/Python/2.7/site-packages/flask/app.py", line 1344, in dispatch_request
    return self.view_functions[rule.endpoint](**req.view_args)
  File "/Users/asraj/github/vmedia-heroku/app.py", line 273, in getLabels
    for label in Label.select():
  File "/Library/Python/2.7/site-packages/peewee.py", line 1721, in __iter__
    return iter(self.execute())
  File "/Library/Python/2.7/site-packages/peewee.py", line 1714, in execute
    self._qr = ResultWrapper(model_class, self._execute(), query_meta)
  File "/Library/Python/2.7/site-packages/peewee.py", line 1470, in _execute
    return self.database.execute_sql(sql, params, self.require_commit)
  File "/Library/Python/2.7/site-packages/peewee.py", line 1885, in execute_sql
    return self.sql_error_handler(exc, sql, params, require_commit)
  File "/Library/Python/2.7/site-packages/peewee.py", line 1871, in sql_error_handler
    raise exception
OperationalError: (2006, 'MySQL server has gone away')
Exception on /getVideos [GET]
Traceback (most recent call last):
  File "/Library/Python/2.7/site-packages/flask/app.py", line 1687, in wsgi_app
    response = self.full_dispatch_request()
  File "/Library/Python/2.7/site-packages/flask/app.py", line 1360, in full_dispatch_request
    rv = self.handle_user_exception(e)
  File "/Library/Python/2.7/site-packages/flask/app.py", line 1358, in full_dispatch_request
    rv = self.dispatch_request()
  File "/Library/Python/2.7/site-packages/flask/app.py", line 1344, in dispatch_request
    return self.view_functions[rule.endpoint](**req.view_args)
  File "/Users/asraj/github/vmedia-heroku/app.py", line 209, in getVideos
    for record in Video.raw("select * from vm_videos where status='N'"):
  File "/Library/Python/2.7/site-packages/peewee.py", line 1527, in __iter__
    return iter(self.execute())
  File "/Library/Python/2.7/site-packages/peewee.py", line 1523, in execute
    self._qr = ResultWrapper(self.model_class, self._execute(), None)
  File "/Library/Python/2.7/site-packages/peewee.py", line 1470, in _execute
    return self.database.execute_sql(sql, params, self.require_commit)
  File "/Library/Python/2.7/site-packages/peewee.py", line 1885, in execute_sql
    return self.sql_error_handler(exc, sql, params, require_commit)
  File "/Library/Python/2.7/site-packages/peewee.py", line 1871, in sql_error_handler
    raise exception
OperationalError: (2006, 'MySQL server has gone away')
2013-12-26 00:49:41.826649- /getLabels called
2013-12-26 01:04:46.613225- /getLabels called
2013-12-26 01:05:06.761776- /getLabels called
2013-12-26 01:12:15.319208- /getLabels called
2013-12-26 01:12:58.969537- /getLabels called
2013-12-26 01:18:32.645610- /getLabels called
2013-12-26 01:19:27.674936- /getLabels called
2013-12-27 01:30:10.220225- /getLabels called
2013-12-27 01:30:11.024078- /getLabels called
2013-12-27 23:55:10.950794- /getLabels called
2013-12-27 23:59:01.735710- /getLabels called
2013-12-28 00:00:38.243144- /getLabels called
2013-12-28 00:05:25.454839- /getLabels called
2013-12-28 00:15:11.100048- /getLabels called
2013-12-28 00:16:46.449307- /getLabels called
2013-12-28 00:18:42.556749- /getLabels called
2013-12-28 00:27:19.719689- /getLabels called
Exception on /saveLabel [POST]
Traceback (most recent call last):
  File "/Library/Python/2.7/site-packages/flask/app.py", line 1687, in wsgi_app
    response = self.full_dispatch_request()
  File "/Library/Python/2.7/site-packages/flask/app.py", line 1360, in full_dispatch_request
    rv = self.handle_user_exception(e)
  File "/Library/Python/2.7/site-packages/flask/app.py", line 1358, in full_dispatch_request
    rv = self.dispatch_request()
  File "/Library/Python/2.7/site-packages/flask/app.py", line 1344, in dispatch_request
    return self.view_functions[rule.endpoint](**req.view_args)
  File "/Users/asraj/github/vmedia-heroku/app.py", line 281, in saveLabel
    category=request.data['category'],
TypeError: string indices must be integers, not str
2013-12-28 00:32:16.448253- /getLabels called
2013-12-28 00:33:52.852785- /getLabels called
2013-12-28 00:36:42.539807- /getLabels called
2013-12-28 00:38:21.514386- /getLabels called
2013-12-28 00:45:34.092237- /getLabels called
2013-12-28 01:07:33.456933- /getLabels called
2013-12-28 01:13:12.895441- /getLabels called
2013-12-28 01:15:10.269159- /getLabels called
2013-12-28 01:17:09.780780- /getLabels called
2013-12-28 01:20:29.569435- /getLabels called
2013-12-28 01:25:18.281536- /getLabels called
Exception on /saveVideo [POST]
Traceback (most recent call last):
  File "/Library/Python/2.7/site-packages/flask/app.py", line 1687, in wsgi_app
    response = self.full_dispatch_request()
  File "/Library/Python/2.7/site-packages/flask/app.py", line 1360, in full_dispatch_request
    rv = self.handle_user_exception(e)
  File "/Library/Python/2.7/site-packages/flask/app.py", line 1358, in full_dispatch_request
    rv = self.dispatch_request()
  File "/Library/Python/2.7/site-packages/flask/app.py", line 1344, in dispatch_request
    return self.view_functions[rule.endpoint](**req.view_args)
  File "/Users/asraj/github/vmedia-heroku/app.py", line 193, in saveVideo
    video = Video.select().where(Video.videoId == int(record['videoId'])).get()
KeyError: 'videoId'
2013-12-28 01:34:50.115097- /getLabels called
2013-12-28 01:36:13.819559- /getLabels called
2013-12-28 01:50:09.668299- /getLabels called
2013-12-28 01:55:53.406969- /getLabels called
2013-12-28 02:05:27.456544- /getLabels called
2013-12-28 02:09:36.278411- /getLabels called
2013-12-28 02:11:21.185004- /getLabels called
Exception on /saveVideo [POST]
Traceback (most recent call last):
  File "/Library/Python/2.7/site-packages/flask/app.py", line 1687, in wsgi_app
    response = self.full_dispatch_request()
  File "/Library/Python/2.7/site-packages/flask/app.py", line 1360, in full_dispatch_request
    rv = self.handle_user_exception(e)
  File "/Library/Python/2.7/site-packages/flask/app.py", line 1358, in full_dispatch_request
    rv = self.dispatch_request()
  File "/Library/Python/2.7/site-packages/flask/app.py", line 1344, in dispatch_request
    return self.view_functions[rule.endpoint](**req.view_args)
  File "/Users/asraj/github/vmedia-heroku/app.py", line 203, in saveVideo
    traceback.print_exc(file=sys.stdout)
NameError: global name 'traceback' is not defined
2013-12-28 02:21:11.748550- /getLabels called
2013-12-28 13:14:56.016394- /getLabels called
2013-12-28 13:16:06.764095- /getLabels called
2013-12-28 13:21:27.774628- /getLabels called
2013-12-28 13:27:48.814506- /getLabels called
2013-12-28 13:29:46.789938- /getLabels called
2013-12-28 15:33:23.817281- /getLabels called
Exception on /saveVideo [POST]
Traceback (most recent call last):
  File "/Library/Python/2.7/site-packages/flask/app.py", line 1687, in wsgi_app
    response = self.full_dispatch_request()
  File "/Library/Python/2.7/site-packages/flask/app.py", line 1360, in full_dispatch_request
    rv = self.handle_user_exception(e)
  File "/Library/Python/2.7/site-packages/flask/app.py", line 1358, in full_dispatch_request
    rv = self.dispatch_request()
  File "/Library/Python/2.7/site-packages/flask/app.py", line 1344, in dispatch_request
    return self.view_functions[rule.endpoint](**req.view_args)
  File "/Users/asraj/github/vmedia-heroku/app.py", line 207, in saveVideo
    traceback.print_exc(file=sys.stdout)
NameError: global name 'traceback' is not defined
Exception on /saveVideo [POST]
Traceback (most recent call last):
  File "/Library/Python/2.7/site-packages/flask/app.py", line 1687, in wsgi_app
    response = self.full_dispatch_request()
  File "/Library/Python/2.7/site-packages/flask/app.py", line 1360, in full_dispatch_request
    rv = self.handle_user_exception(e)
  File "/Library/Python/2.7/site-packages/flask/app.py", line 1358, in full_dispatch_request
    rv = self.dispatch_request()
  File "/Library/Python/2.7/site-packages/flask/app.py", line 1344, in dispatch_request
    return self.view_functions[rule.endpoint](**req.view_args)
  File "/Users/asraj/github/vmedia-heroku/app.py", line 207, in saveVideo
    traceback.print_exc(file=sys.stdout)
NameError: global name 'traceback' is not defined
2013-12-28 15:42:26.614340- /getLabels called
Exception on /saveVideo [POST]
Traceback (most recent call last):
  File "/Library/Python/2.7/site-packages/flask/app.py", line 1687, in wsgi_app
    response = self.full_dispatch_request()
  File "/Library/Python/2.7/site-packages/flask/app.py", line 1360, in full_dispatch_request
    rv = self.handle_user_exception(e)
  File "/Library/Python/2.7/site-packages/flask/app.py", line 1358, in full_dispatch_request
    rv = self.dispatch_request()
  File "/Library/Python/2.7/site-packages/flask/app.py", line 1344, in dispatch_request
    return self.view_functions[rule.endpoint](**req.view_args)
  File "/Users/asraj/github/vmedia-heroku/app.py", line 206, in saveVideo
    traceback.print_exc(file=sys.stdout)
NameError: global name 'traceback' is not defined
2013-12-28 15:47:23.301067- /getLabels called
2013-12-28 16:01:48.611130- /getLabels called
2013-12-28 16:01:51.684856- /getLabels called
2013-12-28 16:03:57.831870- /getLabels called
2013-12-28 16:04:00.004470- /getLabels called
Exception on /searchVideos [GET]
Traceback (most recent call last):
  File "/Library/Python/2.7/site-packages/flask/app.py", line 1687, in wsgi_app
    response = self.full_dispatch_request()
  File "/Library/Python/2.7/site-packages/flask/app.py", line 1361, in full_dispatch_request
    response = self.make_response(rv)
  File "/Library/Python/2.7/site-packages/flask/app.py", line 1450, in make_response
    rv = self.response_class.force_type(rv, request.environ)
  File "/Library/Python/2.7/site-packages/werkzeug/wrappers.py", line 711, in force_type
    response = BaseResponse(*_run_wsgi_app(response, environ))
  File "/Library/Python/2.7/site-packages/werkzeug/test.py", line 818, in run_wsgi_app
    app_iter = app(environ, start_response)
TypeError: 'list' object is not callable
2013-12-28 16:10:00.199095- /getLabels called
2013-12-28 16:10:02.096945- /getLabels called
2013-12-28 16:19:15.382114- /getLabels called
2013-12-28 16:19:48.799075- /getLabels called
2013-12-28 16:20:25.393144- /getLabels called
Exception on /searchVideos [POST]
Traceback (most recent call last):
  File "/Library/Python/2.7/site-packages/flask/app.py", line 1687, in wsgi_app
    response = self.full_dispatch_request()
  File "/Library/Python/2.7/site-packages/flask/app.py", line 1361, in full_dispatch_request
    response = self.make_response(rv)
  File "/Library/Python/2.7/site-packages/flask/app.py", line 1450, in make_response
    rv = self.response_class.force_type(rv, request.environ)
  File "/Library/Python/2.7/site-packages/werkzeug/wrappers.py", line 711, in force_type
    response = BaseResponse(*_run_wsgi_app(response, environ))
  File "/Library/Python/2.7/site-packages/werkzeug/test.py", line 818, in run_wsgi_app
    app_iter = app(environ, start_response)
TypeError: 'list' object is not callable
2013-12-28 16:28:56.828026- /getLabels called
Exception on /searchVideos [POST]
Traceback (most recent call last):
  File "/Library/Python/2.7/site-packages/flask/app.py", line 1687, in wsgi_app
    response = self.full_dispatch_request()
  File "/Library/Python/2.7/site-packages/flask/app.py", line 1361, in full_dispatch_request
    response = self.make_response(rv)
  File "/Library/Python/2.7/site-packages/flask/app.py", line 1450, in make_response
    rv = self.response_class.force_type(rv, request.environ)
  File "/Library/Python/2.7/site-packages/werkzeug/wrappers.py", line 711, in force_type
    response = BaseResponse(*_run_wsgi_app(response, environ))
  File "/Library/Python/2.7/site-packages/werkzeug/test.py", line 818, in run_wsgi_app
    app_iter = app(environ, start_response)
TypeError: 'list' object is not callable
Exception on /searchVideos [POST]
Traceback (most recent call last):
  File "/Library/Python/2.7/site-packages/flask/app.py", line 1687, in wsgi_app
    response = self.full_dispatch_request()
  File "/Library/Python/2.7/site-packages/flask/app.py", line 1361, in full_dispatch_request
    response = self.make_response(rv)
  File "/Library/Python/2.7/site-packages/flask/app.py", line 1450, in make_response
    rv = self.response_class.force_type(rv, request.environ)
  File "/Library/Python/2.7/site-packages/werkzeug/wrappers.py", line 711, in force_type
    response = BaseResponse(*_run_wsgi_app(response, environ))
  File "/Library/Python/2.7/site-packages/werkzeug/test.py", line 818, in run_wsgi_app
    app_iter = app(environ, start_response)
TypeError: 'list' object is not callable
2013-12-28 16:35:23.690044- /getLabels called
Exception on /searchVideos [POST]
Traceback (most recent call last):
  File "/Library/Python/2.7/site-packages/flask/app.py", line 1687, in wsgi_app
    response = self.full_dispatch_request()
  File "/Library/Python/2.7/site-packages/flask/app.py", line 1360, in full_dispatch_request
    rv = self.handle_user_exception(e)
  File "/Library/Python/2.7/site-packages/flask/app.py", line 1358, in full_dispatch_request
    rv = self.dispatch_request()
  File "/Library/Python/2.7/site-packages/flask/app.py", line 1344, in dispatch_request
    return self.view_functions[rule.endpoint](**req.view_args)
  File "/Users/asraj/github/vmedia-heroku/app.py", line 363, in searchVideos
    return jsonify(videos)
  File "/Library/Python/2.7/site-packages/flask/helpers.py", line 197, in jsonify
    return current_app.response_class(json.dumps(dict(*args, **kwargs),
ValueError: dictionary update sequence element #0 has length 4; 2 is required
Exception on /searchVideos [POST]
Traceback (most recent call last):
  File "/Library/Python/2.7/site-packages/flask/app.py", line 1687, in wsgi_app
    response = self.full_dispatch_request()
  File "/Library/Python/2.7/site-packages/flask/app.py", line 1360, in full_dispatch_request
    rv = self.handle_user_exception(e)
  File "/Library/Python/2.7/site-packages/flask/app.py", line 1358, in full_dispatch_request
    rv = self.dispatch_request()
  File "/Library/Python/2.7/site-packages/flask/app.py", line 1344, in dispatch_request
    return self.view_functions[rule.endpoint](**req.view_args)
  File "/Users/asraj/github/vmedia-heroku/app.py", line 363, in searchVideos
    return jsonify(videos)
  File "/Library/Python/2.7/site-packages/flask/helpers.py", line 197, in jsonify
    return current_app.response_class(json.dumps(dict(*args, **kwargs),
ValueError: dictionary update sequence element #0 has length 4; 2 is required
2013-12-28 16:40:23.226112- /getLabels called
